<?xml version="1.0"?>
<robot name="smartcar" xmlns:xacro="http://www.ros.org/wiki/xacro">
  <xacro:property name="M_PI" value="3.141592653589793"/>
  <xacro:property name="wheel_radius" value="0.025"/>
  <xacro:property name="wheel_width" value="0.020"/>
  <xacro:property name="wheel_base" value="0.160"/>
  <xacro:property name="wheel_separation" value="0.160"/>

  <material name="smartcar_blue">
    <color rgba="0.05 0.20 0.80 1"/>
  </material>
  <material name="smartcar_black">
    <color rgba="0.03 0.03 0.03 1"/>
  </material>
  <material name="smartcar_red">
    <color rgba="0.80 0.05 0.05 1"/>
  </material>
  <material name="smartcar_white">
    <color rgba="0.90 0.90 0.90 1"/>
  </material>

  <xacro:macro name="box_inertia" params="mass x y z">
    <inertial>
      <mass value="${mass}"/>
      <inertia
        ixx="${mass * (y * y + z * z) / 12.0}" ixy="0" ixz="0"
        iyy="${mass * (x * x + z * z) / 12.0}" iyz="0"
        izz="${mass * (x * x + y * y) / 12.0}"/>
    </inertial>
  </xacro:macro>

  <xacro:macro name="wheel_link" params="name">
    <link name="${name}">
      <inertial>
        <origin xyz="0 0 0" rpy="${M_PI / 2.0} 0 0"/>
        <mass value="0.10"/>
        <inertia
          ixx="0.00003646" ixy="0" ixz="0"
          iyy="0.00003646" iyz="0"
          izz="0.00003125"/>
      </inertial>
      <visual>
        <origin xyz="0 0 0" rpy="${M_PI / 2.0} 0 0"/>
        <geometry>
          <cylinder radius="${wheel_radius}" length="${wheel_width}"/>
        </geometry>
        <material name="smartcar_black"/>
      </visual>
      <collision>
        <origin xyz="0 0 0" rpy="${M_PI / 2.0} 0 0"/>
        <geometry>
          <cylinder radius="${wheel_radius}" length="${wheel_width}"/>
        </geometry>
      </collision>
    </link>
  </xacro:macro>

  <link name="base_footprint"/>

  <link name="base_link">
    <xacro:box_inertia mass="1.40" x="0.25" y="0.16" z="0.04"/>
    <visual>
      <geometry>
        <box size="0.25 0.16 0.04"/>
      </geometry>
      <material name="smartcar_blue"/>
    </visual>
    <collision>
      <geometry>
        <box size="0.25 0.16 0.04"/>
      </geometry>
    </collision>
  </link>

  <joint name="base_footprint_joint" type="fixed">
    <parent link="base_footprint"/>
    <child link="base_link"/>
    <origin xyz="0 0 0.055" rpy="0 0 0"/>
  </joint>

  <xacro:wheel_link name="rear_left_wheel_link"/>
  <joint name="rear_left_wheel_joint" type="continuous">
    <parent link="base_link"/>
    <child link="rear_left_wheel_link"/>
    <origin xyz="-0.08 0.08 -0.03" rpy="0 0 0"/>
    <axis xyz="0 1 0"/>
    <dynamics damping="0.02" friction="0.01"/>
  </joint>

  <xacro:wheel_link name="rear_right_wheel_link"/>
  <joint name="rear_right_wheel_joint" type="continuous">
    <parent link="base_link"/>
    <child link="rear_right_wheel_link"/>
    <origin xyz="-0.08 -0.08 -0.03" rpy="0 0 0"/>
    <axis xyz="0 1 0"/>
    <dynamics damping="0.02" friction="0.01"/>
  </joint>

  <link name="front_left_steering_link">
    <xacro:box_inertia mass="0.03" x="0.02" y="0.02" z="0.04"/>
    <visual>
      <geometry><box size="0.02 0.02 0.04"/></geometry>
      <material name="smartcar_red"/>
    </visual>
    <collision>
      <geometry><box size="0.02 0.02 0.04"/></geometry>
    </collision>
  </link>
  <joint name="front_left_steering_joint" type="revolute">
    <parent link="base_link"/>
    <child link="front_left_steering_link"/>
    <origin xyz="0.08 0.08 -0.03" rpy="0 0 0"/>
    <axis xyz="0 0 1"/>
    <limit lower="-0.60" upper="0.60" effort="5.0" velocity="4.0"/>
    <dynamics damping="0.10" friction="0.02"/>
  </joint>

  <xacro:wheel_link name="front_left_wheel_link"/>
  <joint name="front_left_wheel_joint" type="continuous">
    <parent link="front_left_steering_link"/>
    <child link="front_left_wheel_link"/>
    <axis xyz="0 1 0"/>
    <dynamics damping="0.02" friction="0.01"/>
  </joint>

  <link name="front_right_steering_link">
    <xacro:box_inertia mass="0.03" x="0.02" y="0.02" z="0.04"/>
    <visual>
      <geometry><box size="0.02 0.02 0.04"/></geometry>
      <material name="smartcar_red"/>
    </visual>
    <collision>
      <geometry><box size="0.02 0.02 0.04"/></geometry>
    </collision>
  </link>
  <joint name="front_right_steering_joint" type="revolute">
    <parent link="base_link"/>
    <child link="front_right_steering_link"/>
    <origin xyz="0.08 -0.08 -0.03" rpy="0 0 0"/>
    <axis xyz="0 0 1"/>
    <limit lower="-0.60" upper="0.60" effort="5.0" velocity="4.0"/>
    <dynamics damping="0.10" friction="0.02"/>
  </joint>

  <xacro:wheel_link name="front_right_wheel_link"/>
  <joint name="front_right_wheel_joint" type="continuous">
    <parent link="front_right_steering_link"/>
    <child link="front_right_wheel_link"/>
    <axis xyz="0 1 0"/>
    <dynamics damping="0.02" friction="0.01"/>
  </joint>

  <link name="sensor_deck_link">
    <xacro:box_inertia mass="0.20" x="0.18" y="0.12" z="0.01"/>
    <visual>
      <geometry><box size="0.18 0.12 0.01"/></geometry>
      <material name="smartcar_white"/>
    </visual>
    <collision>
      <geometry><box size="0.18 0.12 0.01"/></geometry>
    </collision>
  </link>
  <joint name="sensor_deck_joint" type="fixed">
    <parent link="base_link"/>
    <child link="sensor_deck_link"/>
    <origin xyz="0 0 0.055" rpy="0 0 0"/>
  </joint>

  <link name="lidar_link">
    <inertial>
      <mass value="0.10"/>
      <inertia
        ixx="0.00008333" ixy="0" ixz="0"
        iyy="0.00008333" iyz="0"
        izz="0.00012500"/>
    </inertial>
    <visual>
      <geometry><cylinder radius="0.035" length="0.04"/></geometry>
      <material name="smartcar_black"/>
    </visual>
    <collision>
      <geometry><cylinder radius="0.035" length="0.04"/></geometry>
    </collision>
  </link>
  <joint name="lidar_joint" type="fixed">
    <parent link="base_link"/>
    <child link="lidar_link"/>
    <origin xyz="0 0 0.10" rpy="0 0 0"/>
  </joint>

  <link name="camera_link">
    <xacro:box_inertia mass="0.08" x="0.03" y="0.04" z="0.04"/>
    <visual>
      <geometry><box size="0.03 0.04 0.04"/></geometry>
      <material name="smartcar_white"/>
    </visual>
    <collision>
      <geometry><box size="0.03 0.04 0.04"/></geometry>
    </collision>
  </link>
  <joint name="camera_joint" type="fixed">
    <parent link="base_link"/>
    <child link="camera_link"/>
    <origin xyz="0.11 0 0.08" rpy="0 0 0"/>
  </joint>

  <link name="imu_link">
    <xacro:box_inertia mass="0.04" x="0.02" y="0.012" z="0.003"/>
    <visual>
      <geometry><box size="0.02 0.012 0.003"/></geometry>
      <material name="smartcar_red"/>
    </visual>
    <collision>
      <geometry><box size="0.02 0.012 0.003"/></geometry>
    </collision>
  </link>
  <joint name="imu_joint" type="fixed">
    <parent link="base_link"/>
    <child link="imu_link"/>
    <origin xyz="-0.06 0 0.08" rpy="0 0 0"/>
  </joint>

  <gazebo reference="base_link"><material>Gazebo/Blue</material></gazebo>
  <gazebo reference="front_left_steering_link"><material>Gazebo/Red</material></gazebo>
  <gazebo reference="front_right_steering_link"><material>Gazebo/Red</material></gazebo>
  <gazebo reference="rear_left_wheel_link"><material>Gazebo/Black</material></gazebo>
  <gazebo reference="rear_right_wheel_link"><material>Gazebo/Black</material></gazebo>
  <gazebo reference="front_left_wheel_link"><material>Gazebo/Black</material></gazebo>
  <gazebo reference="front_right_wheel_link"><material>Gazebo/Black</material></gazebo>
  <gazebo reference="lidar_link"><material>Gazebo/Black</material></gazebo>

  <gazebo reference="lidar_link">
    <sensor name="lidar_sensor" type="gpu_lidar">
      <always_on>true</always_on>
      <update_rate>20</update_rate>
      <visualize>false</visualize>
      <topic>/smartcar/scan</topic>
      <lidar>
        <scan>
          <horizontal>
            <samples>720</samples>
            <resolution>1</resolution>
            <min_angle>-${M_PI}</min_angle>
            <max_angle>${M_PI}</max_angle>
          </horizontal>
          <vertical>
            <samples>4</samples>
            <resolution>1</resolution>
            <min_angle>-${10.0 * M_PI / 180.0}</min_angle>
            <max_angle>${10.0 * M_PI / 180.0}</max_angle>
          </vertical>
        </scan>
        <range>
          <min>0.10</min>
          <max>30.0</max>
          <resolution>0.01</resolution>
        </range>
        <noise>
          <type>gaussian</type>
          <mean>0.0</mean>
          <stddev>0.01</stddev>
        </noise>
      </lidar>
    </sensor>
  </gazebo>
  <gazebo reference="lidar_joint">
    <preserveFixedJoint>true</preserveFixedJoint>
  </gazebo>

  <gazebo reference="camera_link">
    <material>Gazebo/White</material>
    <sensor name="front_camera" type="camera">
      <always_on>true</always_on>
      <update_rate>20</update_rate>
      <topic>/smartcar/camera/image</topic>
      <camera>
        <horizontal_fov>1.3962634</horizontal_fov>
        <image>
          <width>640</width>
          <height>480</height>
          <format>R8G8B8</format>
        </image>
        <clip>
          <near>0.05</near>
          <far>30.0</far>
        </clip>
      </camera>
    </sensor>
  </gazebo>
  <gazebo reference="camera_joint">
    <preserveFixedJoint>true</preserveFixedJoint>
  </gazebo>

  <gazebo reference="imu_link">
    <sensor name="imu_sensor" type="imu">
      <always_on>true</always_on>
      <update_rate>100</update_rate>
      <topic>/smartcar/imu</topic>
    </sensor>
  </gazebo>
  <gazebo reference="imu_joint">
    <preserveFixedJoint>true</preserveFixedJoint>
  </gazebo>

  <gazebo>
    <plugin
      filename="gz-sim-ackermann-steering-system"
      name="gz::sim::systems::AckermannSteering">
      <left_joint>rear_left_wheel_joint</left_joint>
      <right_joint>rear_right_wheel_joint</right_joint>
      <left_steering_joint>front_left_steering_joint</left_steering_joint>
      <right_steering_joint>front_right_steering_joint</right_steering_joint>
      <kingpin_width>${wheel_separation}</kingpin_width>
      <steering_limit>0.60</steering_limit>
      <wheel_base>${wheel_base}</wheel_base>
      <wheel_separation>${wheel_separation}</wheel_separation>
      <wheel_radius>${wheel_radius}</wheel_radius>
      <topic>/smartcar/cmd_vel</topic>
      <odom_topic>/smartcar/odom</odom_topic>
      <tf_topic>/smartcar/tf</tf_topic>
      <frame_id>odom</frame_id>
      <child_frame_id>base_footprint</child_frame_id>
      <odom_publish_frequency>30</odom_publish_frequency>
      <min_velocity>-0.8</min_velocity>
      <max_velocity>0.8</max_velocity>
      <min_acceleration>-2.0</min_acceleration>
      <max_acceleration>2.0</max_acceleration>
    </plugin>
    <plugin
      filename="gz-sim-joint-state-publisher-system"
      name="gz::sim::systems::JointStatePublisher">
      <topic>/smartcar/joint_states</topic>
      <joint_name>rear_left_wheel_joint</joint_name>
      <joint_name>rear_right_wheel_joint</joint_name>
      <joint_name>front_left_wheel_joint</joint_name>
      <joint_name>front_right_wheel_joint</joint_name>
      <joint_name>front_left_steering_joint</joint_name>
      <joint_name>front_right_steering_joint</joint_name>
    </plugin>
  </gazebo>
</robot>
